Workbook

Sheet Title Race
A1: 2026 F1 TITLE RACE - WHO CAN STILL WIN
A2: Updates automatically from the 'F1 Championship' sheet. Enter results there; only the yellow cells on this sheet are editable.
M3: How to read: a driver is still in it while their line finishes at or above the dashed leader line. When a line drops below it, that driver is mathematically out.
A4: 1. POINTS STILL ON THE TABLE
A5: Event | B5: Start | C5: Sprint | D5: Singapore | E5: Houston | F5: Mexico | G5: Brazil | H5: Las Vegas | I5: Qatar | J5: Abu Dhabi | K5: Total
A6: Max points available | C6: 8 | D6: 25 | E6: 25 | F6: 25 | G6: 25 | H6: 25 | I6: 25 | J6: 25 | K6: =SUM(C6:J6) -> 183
A7: Result entered? | C7: =IF(COUNT('F1 Championship'!D$5:D$27)>0,"Yes","No") -> No | D7: =IF(COUNT('F1 Championship'!E$5:E$27)>0,"Yes","No") -> No | E7: =IF(COUNT('F1 Championship'!F$5:F$27)>0,"Yes","No") -> No | F7: =IF(COUNT('F1 Championship'!G$5:G$27)>0,"Yes","No") -> No | G7: =IF(COUNT('F1 Championship'!H$5:H$27)>0,"Yes","No") -> No | H7: =IF(COUNT('F1 Championship'!I$5:I$27)>0,"Yes","No") -> No | I7: =IF(COUNT('F1 Championship'!J$5:J$27)>0,"Yes","No") -> No | J7: =IF(COUNT('F1 Championship'!K$5:K$27)>0,"Yes","No") -> No
A8: Points left after event | B8: =SUM(C6:J6) -> 183 | C8: =SUM(D6:$J$6) -> 175 | D8: =SUM(E6:$J$6) -> 150 | E8: =SUM(F6:$J$6) -> 125 | F8: =SUM(G6:$J$6) -> 100 | G8: =SUM(H6:$J$6) -> 75 | H8: =SUM(I6:$J$6) -> 50 | I8: =SUM(J6:$J$6) -> 25 | J8: 0
A9: Points remaining now | B9: =SUMIF(C7:J7,"No",C6:J6) -> 183 | C9: Max points still available in events with no results entered yet
A11: 2. CHAMPIONSHIP STATUS (all drivers)
A12: Driver | B12: Team | C12: Current pts | D12: Max possible | E12: Gap to leader | F12: Status
A13: ='F1 Championship'!A5 -> Kimi Antonelli | B13: ='F1 Championship'!B5 -> Mercedes | C13: ='F1 Championship'!M5 -> 320 | D13: =C13+$B$9 -> 503 | E13: =MAX($C$13:$C$35)-C13 -> 0 | F13: =IF(C13=MAX($C$13:$C$35),"Leader",IF(D13>MAX($C$13:$C$35),"Can win",IF(D13=MAX($C$13:$C$35),"Tie only","Eliminated"))) -> Leader
A14: ='F1 Championship'!A6 -> George Russell | B14: ='F1 Championship'!B6 -> Mercedes | C14: ='F1 Championship'!M6 -> 236 | D14: =C14+$B$9 -> 419 | E14: =MAX($C$13:$C$35)-C14 -> 84 | F14: =IF(C14=MAX($C$13:$C$35),"Leader",IF(D14>MAX($C$13:$C$35),"Can win",IF(D14=MAX($C$13:$C$35),"Tie only","Eliminated"))) -> Can win
A15: ='F1 Championship'!A7 -> Lewis Hamilton | B15: ='F1 Championship'!B7 -> Ferrari | C15: ='F1 Championship'!M7 -> 214 | D15: =C15+$B$9 -> 397 | E15: =MAX($C$13:$C$35)-C15 -> 106 | F15: =IF(C15=MAX($C$13:$C$35),"Leader",IF(D15>MAX($C$13:$C$35),"Can win",IF(D15=MAX($C$13:$C$35),"Tie only","Eliminated"))) -> Can win
A16: ='F1 Championship'!A8 -> Charles Leclerc | B16: ='F1 Championship'!B8 -> Ferrari | C16: ='F1 Championship'!M8 -> 191 | D16: =C16+$B$9 -> 374 | E16: =MAX($C$13:$C$35)-C16 -> 129 | F16: =IF(C16=MAX($C$13:$C$35),"Leader",IF(D16>MAX($C$13:$C$35),"Can win",IF(D16=MAX($C$13:$C$35),"Tie only","Eliminated"))) -> Can win
A17: ='F1 Championship'!A9 -> Lando Norris | B17: ='F1 Championship'!B9 -> McLaren | C17: ='F1 Championship'!M9 -> 188 | D17: =C17+$B$9 -> 371 | E17: =MAX($C$13:$C$35)-C17 -> 132 | F17: =IF(C17=MAX($C$13:$C$35),"Leader",IF(D17>MAX($C$13:$C$35),"Can win",IF(D17=MAX($C$13:$C$35),"Tie only","Eliminated"))) -> Can win
A18: ='F1 Championship'!A10 -> Max Verstappen | B18: ='F1 Championship'!B10 -> Red Bull Racing | C18: ='F1 Championship'!M10 -> 188 | D18: =C18+$B$9 -> 371 | E18: =MAX($C$13:$C$35)-C18 -> 132 | F18: =IF(C18=MAX($C$13:$C$35),"Leader",IF(D18>MAX($C$13:$C$35),"Can win",IF(D18=MAX($C$13:$C$35),"Tie only","Eliminated"))) -> Can win
A19: ='F1 Championship'!A11 -> Oscar Piastri | B19: ='F1 Championship'!B11 -> McLaren | C19: ='F1 Championship'!M11 -> 128 | D19: =C19+$B$9 -> 311 | E19: =MAX($C$13:$C$35)-C19 -> 192 | F19: =IF(C19=MAX($C$13:$C$35),"Leader",IF(D19>MAX($C$13:$C$35),"Can win",IF(D19=MAX($C$13:$C$35),"Tie only","Eliminated"))) -> Eliminated
A20: ='F1 Championship'!A12 -> Isack Hadjar | B20: ='F1 Championship'!B12 -> Red Bull Racing | C20: ='F1 Championship'!M12 -> 96 | D20: =C20+$B$9 -> 279 | E20: =MAX($C$13:$C$35)-C20 -> 224 | F20: =IF(C20=MAX($C$13:$C$35),"Leader",IF(D20>MAX($C$13:$C$35),"Can win",IF(D20=MAX($C$13:$C$35),"Tie only","Eliminated"))) -> Eliminated
A21: ='F1 Championship'!A13 -> Liam Lawson | B21: ='F1 Championship'!B13 -> Racing Bulls | C21: ='F1 Championship'!M13 -> 65 | D21: =C21+$B$9 -> 248 | E21: =MAX($C$13:$C$35)-C21 -> 255 | F21: =IF(C21=MAX($C$13:$C$35),"Leader",IF(D21>MAX($C$13:$C$35),"Can win",IF(D21=MAX($C$13:$C$35),"Tie only","Eliminated"))) -> Eliminated
A22: ='F1 Championship'!A14 -> Pierre Gasly | B22: ='F1 Championship'!B14 -> Alpine | C22: ='F1 Championship'!M14 -> 41 | D22: =C22+$B$9 -> 224 | E22: =MAX($C$13:$C$35)-C22 -> 279 | F22: =IF(C22=MAX($C$13:$C$35),"Leader",IF(D22>MAX($C$13:$C$35),"Can win",IF(D22=MAX($C$13:$C$35),"Tie only","Eliminated"))) -> Eliminated
A23: ='F1 Championship'!A15 -> Arvid Lindblad | B23: ='F1 Championship'!B15 -> Racing Bulls | C23: ='F1 Championship'!M15 -> 38 | D23: =C23+$B$9 -> 221 | E23: =MAX($C$13:$C$35)-C23 -> 282 | F23: =IF(C23=MAX($C$13:$C$35),"Leader",IF(D23>MAX($C$13:$C$35),"Can win",IF(D23=MAX($C$13:$C$35),"Tie only","Eliminated"))) -> Eliminated
A24: ='F1 Championship'!A16 -> Franco Colapinto | B24: ='F1 Championship'!B16 -> Alpine | C24: ='F1 Championship'!M16 -> 27 | D24: =C24+$B$9 -> 210 | E24: =MAX($C$13:$C$35)-C24 -> 293 | F24: =IF(C24=MAX($C$13:$C$35),"Leader",IF(D24>MAX($C$13:$C$35),"Can win",IF(D24=MAX($C$13:$C$35),"Tie only","Eliminated"))) -> Eliminated
... A35: ='F1 Championship'!A27 -> Sergio Perez | B35: ='F1 Championship'!B27 -> Cadillac | C35: ='F1 Championship'!M27 -> 0 | D35: =C35+$B$9 -> 183 | E35: =MAX($C$13:$C$35)-C35 -> 320 | F35: =IF(C35=MAX($C$13:$C$35),"Leader",IF(D35>MAX($C$13:$C$35),"Can win",IF(D35=MAX($C$13:$C$35),"Tie only","Eliminated"))) -> Eliminated
A36: Can win = max possible beats the leader's current total. Tie only = can at best draw level (decided on countback of wins). Eliminated = cannot catch the leader.
A38: 3. RUNNING POINTS TOTAL AFTER EACH EVENT
A39: Driver | B39: Start | C39: Sprint | D39: Singapore | E39: Houston | F39: Mexico | G39: Brazil | H39: Las Vegas | I39: Qatar | J39: Abu Dhabi
A40: ='F1 Championship'!A5 -> Kimi Antonelli | B40: ='F1 Championship'!C5 -> 320 | C40: =B40+IF('F1 Championship'!D5="",0,IFERROR(CHOOSE('F1 Championship'!D5,8,7,6,5,4,3,2,1,0,0,0,0,0,0,0,0,0,0,0,0),0)) -> 320 | D40: =C40+IF('F1 Championship'!E5="",0,IFERROR(CHOOSE('F1 Championship'!E5,25,18,15,12,10,8,6,4,2,1,0,0,0,0,0,0,0,0,0,0),0)) -> 320 | E40: =D40+IF('F1 Championship'!F5="",0,IFERROR(CHOOSE('F1 Championship'!F5,25,18,15,12,10,8,6,4,2,1,0,0,0,0,0,0,0,0,0,0),0)) -> 320 | F40: =E40+IF('F1 Championship'!G5="",0,IFERROR(CHOOSE('F1 Championship'!G5,25,18,15,12,10,8,6,4,2,1,0,0,0,0,0,0,0,0,0,0),0)) -> 320 | G40: =F40+IF('F1 Championship'!H5="",0,IFERROR(CHOOSE('F1 Championship'!H5,25,18,15,12,10,8,6,4,2,1,0,0,0,0,0,0,0,0,0,0),0)) -> 320 | H40: =G40+IF('F1 Championship'!I5="",0,IFERROR(CHOOSE('F1 Championship'!I5,25,18,15,12,10,8,6,4,2,1,0,0,0,0,0,0,0,0,0,0),0)) -> 320 | I40: =H40+IF('F1 Championship'!J5="",0,IFERROR(CHOOSE('F1 Championship'!J5,25,18,15,12,10,8,6,4,2,1,0,0,0,0,0,0,0,0,0,0),0)) -> 320 | J40: =I40+IF('F1 Championship'!K5="",0,IFERROR(CHOOSE('F1 Championship'!K5,25,18,15,12,10,8,6,4,2,1,0,0,0,0,0,0,0,0,0,0),0)) -> 320
A41: ='F1 Championship'!A6 -> George Russell | B41: ='F1 Championship'!C6 -> 236 | C41: =B41+IF('F1 Championship'!D6="",0,IFERROR(CHOOSE('F1 Championship'!D6,8,7,6,5,4,3,2,1,0,0,0,0,0,0,0,0,0,0,0,0),0)) -> 236 | D41: =C41+IF('F1 Championship'!E6="",0,IFERROR(CHOOSE('F1 Championship'!E6,25,18,15,12,10,8,6,4,2,1,0,0,0,0,0,0,0,0,0,0),0)) -> 236 | E41: =D41+IF('F1 Championship'!F6="",0,IFERROR(CHOOSE('F1 Championship'!F6,25,18,15,12,10,8,6,4,2,1,0,0,0,0,0,0,0,0,0,0),0)) -> 236 | F41: =E41+IF('F1 Championship'!G6="",0,IFERROR(CHOOSE('F1 Championship'!G6,25,18,15,12,10,8,6,4,2,1,0,0,0,0,0,0,0,0,0,0),0)) -> 236 | G41: =F41+IF('F1 Championship'!H6="",0,IFERROR(CHOOSE('F1 Championship'!H6,25,18,15,12,10,8,6,4,2,1,0,0,0,0,0,0,0,0,0,0),0)) -> 236 | H41: =G41+IF('F1 Championship'!I6="",0,IFERROR(CHOOSE('F1 Championship'!I6,25,18,15,12,10,8,6,4,2,1,0,0,0,0,0,0,0,0,0,0),0)) -> 236 | I41: =H41+IF('F1 Championship'!J6="",0,IFERROR(CHOOSE('F1 Championship'!J6,25,18,15,12,10,8,6,4,2,1,0,0,0,0,0,0,0,0,0,0),0)) -> 236 | J41: =I41+IF('F1 Championship'!K6="",0,IFERROR(CHOOSE('F1 Championship'!K6,25,18,15,12,10,8,6,4,2,1,0,0,0,0,0,0,0,0,0,0),0)) -> 236
A42: ='F1 Championship'!A7 -> Lewis Hamilton | B42: ='F1 Championship'!C7 -> 214 | C42: =B42+IF('F1 Championship'!D7="",0,IFERROR(CHOOSE('F1 Championship'!D7,8,7,6,5,4,3,2,1,0,0,0,0,0,0,0,0,0,0,0,0),0)) -> 214 | D42: =C42+IF('F1 Championship'!E7="",0,IFERROR(CHOOSE('F1 Championship'!E7,25,18,15,12,10,8,6,4,2,1,0,0,0,0,0,0,0,0,0,0),0)) -> 214 | E42: =D42+IF('F1 Championship'!F7="",0,IFERROR(CHOOSE('F1 Championship'!F7,25,18,15,12,10,8,6,4,2,1,0,0,0,0,0,0,0,0,0,0),0)) -> 214 | F42: =E42+IF('F1 Championship'!G7="",0,IFERROR(CHOOSE('F1 Championship'!G7,25,18,15,12,10,8,6,4,2,1,0,0,0,0,0,0,0,0,0,0),0)) -> 214 | G42: =F42+IF('F1 Championship'!H7="",0,IFERROR(CHOOSE('F1 Championship'!H7,25,18,15,12,10,8,6,4,2,1,0,0,0,0,0,0,0,0,0,0),0)) -> 214 | H42: =G42+IF('F1 Championship'!I7="",0,IFERROR(CHOOSE('F1 Championship'!I7,25,18,15,12,10,8,6,4,2,1,0,0,0,0,0,0,0,0,0,0),0)) -> 214 | I42: =H42+IF('F1 Championship'!J7="",0,IFERROR(CHOOSE('F1 Championship'!J7,25,18,15,12,10,8,6,4,2,1,0,0,0,0,0,0,0,0,0,0),0)) -> 214 | J42: =I42+IF('F1 Championship'!K7="",0,IFERROR(CHOOSE('F1 Championship'!K7,25,18,15,12,10,8,6,4,2,1,0,0,0,0,0,0,0,0,0,0),0)) -> 214
A43: ='F1 Championship'!A8 -> Charles Leclerc | B43: ='F1 Championship'!C8 -> 191 | C43: =B43+IF('F1 Championship'!D8="",0,IFERROR(CHOOSE('F1 Championship'!D8,8,7,6,5,4,3,2,1,0,0,0,0,0,0,0,0,0,0,0,0),0)) -> 191 | D43: =C43+IF('F1 Championship'!E8="",0,IFERROR(CHOOSE('F1 Championship'!E8,25,18,15,12,10,8,6,4,2,1,0,0,0,0,0,0,0,0,0,0),0)) -> 191 | E43: =D43+IF('F1 Championship'!F8="",0,IFERROR(CHOOSE('F1 Championship'!F8,25,18,15,12,10,8,6,4,2,1,0,0,0,0,0,0,0,0,0,0),0)) -> 191 | F43: =E43+IF('F1 Championship'!G8="",0,IFERROR(CHOOSE('F1 Championship'!G8,25,18,15,12,10,8,6,4,2,1,0,0,0,0,0,0,0,0,0,0),0)) -> 191 | G43: =F43+IF('F1 Championship'!H8="",0,IFERROR(CHOOSE('F1 Championship'!H8,25,18,15,12,10,8,6,4,2,1,0,0,0,0,0,0,0,0,0,0),0)) -> 191 | H43: =G43+IF('F1 Championship'!I8="",0,IFERROR(CHOOSE('F1 Championship'!I8,25,18,15,12,10,8,6,4,2,1,0,0,0,0,0,0,0,0,0,0),0)) -> 191 | I43: =H43+IF('F1 Championship'!J8="",0,IFERROR(CHOOSE('F1 Championship'!J8,25,18,15,12,10,8,6,4,2,1,0,0,0,0,0,0,0,0,0,0),0)) -> 191 | J43: =I43+IF('F1 Championship'!K8="",0,IFERROR(CHOOSE('F1 Championship'!K8,25,18,15,12,10,8,6,4,2,1,0,0,0,0,0,0,0,0,0,0),0)) -> 191
A44: ='F1 Championship'!A9 -> Lando Norris | B44: ='F1 Championship'!C9 -> 188 | C44: =B44+IF('F1 Championship'!D9="",0,IFERROR(CHOOSE('F1 Championship'!D9,8,7,6,5,4,3,2,1,0,0,0,0,0,0,0,0,0,0,0,0),0)) -> 188 | D44: =C44+IF('F1 Championship'!E9="",0,IFERROR(CHOOSE('F1 Championship'!E9,25,18,15,12,10,8,6,4,2,1,0,0,0,0,0,0,0,0,0,0),0)) -> 188 | E44: =D44+IF('F1 Championship'!F9="",0,IFERROR(CHOOSE('F1 Championship'!F9,25,18,15,12,10,8,6,4,2,1,0,0,0,0,0,0,0,0,0,0),0)) -> 188 | F44: =E44+IF('F1 Championship'!G9="",0,IFERROR(CHOOSE('F1 Championship'!G9,25,18,15,12,10,8,6,4,2,1,0,0,0,0,0,0,0,0,0,0),0)) -> 188 | G44: =F44+IF('F1 Championship'!H9="",0,IFERROR(CHOOSE('F1 Championship'!H9,25,18,15,12,10,8,6,4,2,1,0,0,0,0,0,0,0,0,0,0),0)) -> 188 | H44: =G44+IF('F1 Championship'!I9="",0,IFERROR(CHOOSE('F1 Championship'!I9,25,18,15,12,10,8,6,4,2,1,0,0,0,0,0,0,0,0,0,0),0)) -> 188 | I44: =H44+IF('F1 Championship'!J9="",0,IFERROR(CHOOSE('F1 Championship'!J9,25,18,15,12,10,8,6,4,2,1,0,0,0,0,0,0,0,0,0,0),0)) -> 188 | J44: =I44+IF('F1 Championship'!K9="",0,IFERROR(CHOOSE('F1 Championship'!K9,25,18,15,12,10,8,6,4,2,1,0,0,0,0,0,0,0,0,0,0),0)) -> 188
A45: ='F1 Championship'!A10 -> Max Verstappen | B45: ='F1 Championship'!C10 -> 188 | C45: =B45+IF('F1 Championship'!D10="",0,IFERROR(CHOOSE('F1 Championship'!D10,8,7,6,5,4,3,2,1,0,0,0,0,0,0,0,0,0,0,0,0),0)) -> 188 | D45: =C45+IF('F1 Championship'!E10="",0,IFERROR(CHOOSE('F1 Championship'!E10,25,18,15,12,10,8,6,4,2,1,0,0,0,0,0,0,0,0,0,0),0)) -> 188 | E45: =D45+IF('F1 Championship'!F10="",0,IFERROR(CHOOSE('F1 Championship'!F10,25,18,15,12,10,8,6,4,2,1,0,0,0,0,0,0,0,0,0,0),0)) -> 188 | F45: =E45+IF('F1 Championship'!G10="",0,IFERROR(CHOOSE('F1 Championship'!G10,25,18,15,12,10,8,6,4,2,1,0,0,0,0,0,0,0,0,0,0),0)) -> 188 | G45: =F45+IF('F1 Championship'!H10="",0,IFERROR(CHOOSE('F1 Championship'!H10,25,18,15,12,10,8,6,4,2,1,0,0,0,0,0,0,0,0,0,0),0)) -> 188 | H45: =G45+IF('F1 Championship'!I10="",0,IFERROR(CHOOSE('F1 Championship'!I10,25,18,15,12,10,8,6,4,2,1,0,0,0,0,0,0,0,0,0,0),0)) -> 188 | I45: =H45+IF('F1 Championship'!J10="",0,IFERROR(CHOOSE('F1 Championship'!J10,25,18,15,12,10,8,6,4,2,1,0,0,0,0,0,0,0,0,0,0),0)) -> 188 | J45: =I45+IF('F1 Championship'!K10="",0,IFERROR(CHOOSE('F1 Championship'!K10,25,18,15,12,10,8,6,4,2,1,0,0,0,0,0,0,0,0,0,0),0)) -> 188
A46: ='F1 Championship'!A11 -> Oscar Piastri | B46: ='F1 Championship'!C11 -> 128 | C46: =B46+IF('F1 Championship'!D11="",0,IFERROR(CHOOSE('F1 Championship'!D11,8,7,6,5,4,3,2,1,0,0,0,0,0,0,0,0,0,0,0,0),0)) -> 128 | D46: =C46+IF('F1 Championship'!E11="",0,IFERROR(CHOOSE('F1 Championship'!E11,25,18,15,12,10,8,6,4,2,1,0,0,0,0,0,0,0,0,0,0),0)) -> 128 | E46: =D46+IF('F1 Championship'!F11="",0,IFERROR(CHOOSE('F1 Championship'!F11,25,18,15,12,10,8,6,4,2,1,0,0,0,0,0,0,0,0,0,0),0)) -> 128 | F46: =E46+IF('F1 Championship'!G11="",0,IFERROR(CHOOSE('F1 Championship'!G11,25,18,15,12,10,8,6,4,2,1,0,0,0,0,0,0,0,0,0,0),0)) -> 128 | G46: =F46+IF('F1 Championship'!H11="",0,IFERROR(CHOOSE('F1 Championship'!H11,25,18,15,12,10,8,6,4,2,1,0,0,0,0,0,0,0,0,0,0),0)) -> 128 | H46: =G46+IF('F1 Championship'!I11="",0,IFERROR(CHOOSE('F1 Championship'!I11,25,18,15,12,10,8,6,4,2,1,0,0,0,0,0,0,0,0,0,0),0)) -> 128 | I46: =H46+IF('F1 Championship'!J11="",0,IFERROR(CHOOSE('F1 Championship'!J11,25,18,15,12,10,8,6,4,2,1,0,0,0,0,0,0,0,0,0,0),0)) -> 128 | J46: =I46+IF('F1 Championship'!K11="",0,IFERROR(CHOOSE('F1 Championship'!K11,25,18,15,12,10,8,6,4,2,1,0,0,0,0,0,0,0,0,0,0),0)) -> 128
A47: ='F1 Championship'!A12 -> Isack Hadjar | B47: ='F1 Championship'!C12 -> 96 | C47: =B47+IF('F1 Championship'!D12="",0,IFERROR(CHOOSE('F1 Championship'!D12,8,7,6,5,4,3,2,1,0,0,0,0,0,0,0,0,0,0,0,0),0)) -> 96 | D47: =C47+IF('F1 Championship'!E12="",0,IFERROR(CHOOSE('F1 Championship'!E12,25,18,15,12,10,8,6,4,2,1,0,0,0,0,0,0,0,0,0,0),0)) -> 96 | E47: =D47+IF('F1 Championship'!F12="",0,IFERROR(CHOOSE('F1 Championship'!F12,25,18,15,12,10,8,6,4,2,1,0,0,0,0,0,0,0,0,0,0),0)) -> 96 | F47: =E47+IF('F1 Championship'!G12="",0,IFERROR(CHOOSE('F1 Championship'!G12,25,18,15,12,10,8,6,4,2,1,0,0,0,0,0,0,0,0,0,0),0)) -> 96 | G47: =F47+IF('F1 Championship'!H12="",0,IFERROR(CHOOSE('F1 Championship'!H12,25,18,15,12,10,8,6,4,2,1,0,0,0,0,0,0,0,0,0,0),0)) -> 96 | H47: =G47+IF('F1 Championship'!I12="",0,IFERROR(CHOOSE('F1 Championship'!I12,25,18,15,12,10,8,6,4,2,1,0,0,0,0,0,0,0,0,0,0),0)) -> 96 | I47: =H47+IF('F1 Championship'!J12="",0,IFERROR(CHOOSE('F1 Championship'!J12,25,18,15,12,10,8,6,4,2,1,0,0,0,0,0,0,0,0,0,0),0)) -> 96 | J47: =I47+IF('F1 Championship'!K12="",0,IFERROR(CHOOSE('F1 Championship'!K12,25,18,15,12,10,8,6,4,2,1,0,0,0,0,0,0,0,0,0,0),0)) -> 96
A48: ='F1 Championship'!A13 -> Liam Lawson | B48: ='F1 Championship'!C13 -> 65 | C48: =B48+IF('F1 Championship'!D13="",0,IFERROR(CHOOSE('F1 Championship'!D13,8,7,6,5,4,3,2,1,0,0,0,0,0,0,0,0,0,0,0,0),0)) -> 65 | D48: =C48+IF('F1 Championship'!E13="",0,IFERROR(CHOOSE('F1 Championship'!E13,25,18,15,12,10,8,6,4,2,1,0,0,0,0,0,0,0,0,0,0),0)) -> 65 | E48: =D48+IF('F1 Championship'!F13="",0,IFERROR(CHOOSE('F1 Championship'!F13,25,18,15,12,10,8,6,4,2,1,0,0,0,0,0,0,0,0,0,0),0)) -> 65 | F48: =E48+IF('F1 Championship'!G13="",0,IFERROR(CHOOSE('F1 Championship'!G13,25,18,15,12,10,8,6,4,2,1,0,0,0,0,0,0,0,0,0,0),0)) -> 65 | G48: =F48+IF('F1 Championship'!H13="",0,IFERROR(CHOOSE('F1 Championship'!H13,25,18,15,12,10,8,6,4,2,1,0,0,0,0,0,0,0,0,0,0),0)) -> 65 | H48: =G48+IF('F1 Championship'!I13="",0,IFERROR(CHOOSE('F1 Championship'!I13,25,18,15,12,10,8,6,4,2,1,0,0,0,0,0,0,0,0,0,0),0)) -> 65 | I48: =H48+IF('F1 Championship'!J13="",0,IFERROR(CHOOSE('F1 Championship'!J13,25,18,15,12,10,8,6,4,2,1,0,0,0,0,0,0,0,0,0,0),0)) -> 65 | J48: =I48+IF('F1 Championship'!K13="",0,IFERROR(CHOOSE('F1 Championship'!K13,25,18,15,12,10,8,6,4,2,1,0,0,0,0,0,0,0,0,0,0),0)) -> 65
A49: ='F1 Championship'!A14 -> Pierre Gasly | B49: ='F1 Championship'!C14 -> 41 | C49: =B49+IF('F1 Championship'!D14="",0,IFERROR(CHOOSE('F1 Championship'!D14,8,7,6,5,4,3,2,1,0,0,0,0,0,0,0,0,0,0,0,0),0)) -> 41 | D49: =C49+IF('F1 Championship'!E14="",0,IFERROR(CHOOSE('F1 Championship'!E14,25,18,15,12,10,8,6,4,2,1,0,0,0,0,0,0,0,0,0,0),0)) -> 41 | E49: =D49+IF('F1 Championship'!F14="",0,IFERROR(CHOOSE('F1 Championship'!F14,25,18,15,12,10,8,6,4,2,1,0,0,0,0,0,0,0,0,0,0),0)) -> 41 | F49: =E49+IF('F1 Championship'!G14="",0,IFERROR(CHOOSE('F1 Championship'!G14,25,18,15,12,10,8,6,4,2,1,0,0,0,0,0,0,0,0,0,0),0)) -> 41 | G49: =F49+IF('F1 Championship'!H14="",0,IFERROR(CHOOSE('F1 Championship'!H14,25,18,15,12,10,8,6,4,2,1,0,0,0,0,0,0,0,0,0,0),0)) -> 41 | H49: =G49+IF('F1 Championship'!I14="",0,IFERROR(CHOOSE('F1 Championship'!I14,25,18,15,12,10,8,6,4,2,1,0,0,0,0,0,0,0,0,0,0),0)) -> 41 | I49: =H49+IF('F1 Championship'!J14="",0,IFERROR(CHOOSE('F1 Championship'!J14,25,18,15,12,10,8,6,4,2,1,0,0,0,0,0,0,0,0,0,0),0)) -> 41 | J49: =I49+IF('F1 Championship'!K14="",0,IFERROR(CHOOSE('F1 Championship'!K14,25,18,15,12,10,8,6,4,2,1,0,0,0,0,0,0,0,0,0,0),0)) -> 41
A50: ='F1 Championship'!A15 -> Arvid Lindblad | B50: ='F1 Championship'!C15 -> 38 | C50: =B50+IF('F1 Championship'!D15="",0,IFERROR(CHOOSE('F1 Championship'!D15,8,7,6,5,4,3,2,1,0,0,0,0,0,0,0,0,0,0,0,0),0)) -> 38 | D50: =C50+IF('F1 Championship'!E15="",0,IFERROR(CHOOSE('F1 Championship'!E15,25,18,15,12,10,8,6,4,2,1,0,0,0,0,0,0,0,0,0,0),0)) -> 38 | E50: =D50+IF('F1 Championship'!F15="",0,IFERROR(CHOOSE('F1 Championship'!F15,25,18,15,12,10,8,6,4,2,1,0,0,0,0,0,0,0,0,0,0),0)) -> 38 | F50: =E50+IF('F1 Championship'!G15="",0,IFERROR(CHOOSE('F1 Championship'!G15,25,18,15,12,10,8,6,4,2,1,0,0,0,0,0,0,0,0,0,0),0)) -> 38 | G50: =F50+IF('F1 Championship'!H15="",0,IFERROR(CHOOSE('F1 Championship'!H15,25,18,15,12,10,8,6,4,2,1,0,0,0,0,0,0,0,0,0,0),0)) -> 38 | H50: =G50+IF('F1 Championship'!I15="",0,IFERROR(CHOOSE('F1 Championship'!I15,25,18,15,12,10,8,6,4,2,1,0,0,0,0,0,0,0,0,0,0),0)) -> 38 | I50: =H50+IF('F1 Championship'!J15="",0,IFERROR(CHOOSE('F1 Championship'!J15,25,18,15,12,10,8,6,4,2,1,0,0,0,0,0,0,0,0,0,0),0)) -> 38 | J50: =I50+IF('F1 Championship'!K15="",0,IFERROR(CHOOSE('F1 Championship'!K15,25,18,15,12,10,8,6,4,2,1,0,0,0,0,0,0,0,0,0,0),0)) -> 38
A51: ='F1 Championship'!A16 -> Franco Colapinto | B51: ='F1 Championship'!C16 -> 27 | C51: =B51+IF('F1 Championship'!D16="",0,IFERROR(CHOOSE('F1 Championship'!D16,8,7,6,5,4,3,2,1,0,0,0,0,0,0,0,0,0,0,0,0),0)) -> 27 | D51: =C51+IF('F1 Championship'!E16="",0,IFERROR(CHOOSE('F1 Championship'!E16,25,18,15,12,10,8,6,4,2,1,0,0,0,0,0,0,0,0,0,0),0)) -> 27 | E51: =D51+IF('F1 Championship'!F16="",0,IFERROR(CHOOSE('F1 Championship'!F16,25,18,15,12,10,8,6,4,2,1,0,0,0,0,0,0,0,0,0,0),0)) -> 27 | F51: =E51+IF('F1 Championship'!G16="",0,IFERROR(CHOOSE('F1 Championship'!G16,25,18,15,12,10,8,6,4,2,1,0,0,0,0,0,0,0,0,0,0),0)) -> 27 | G51: =F51+IF('F1 Championship'!H16="",0,IFERROR(CHOOSE('F1 Championship'!H16,25,18,15,12,10,8,6,4,2,1,0,0,0,0,0,0,0,0,0,0),0)) -> 27 | H51: =G51+IF('F1 Championship'!I16="",0,IFERROR(CHOOSE('F1 Championship'!I16,25,18,15,12,10,8,6,4,2,1,0,0,0,0,0,0,0,0,0,0),0)) -> 27 | I51: =H51+IF('F1 Championship'!J16="",0,IFERROR(CHOOSE('F1 Championship'!J16,25,18,15,12,10,8,6,4,2,1,0,0,0,0,0,0,0,0,0,0),0)) -> 27 | J51: =I51+IF('F1 Championship'!K16="",0,IFERROR(CHOOSE('F1 Championship'!K16,25,18,15,12,10,8,6,4,2,1,0,0,0,0,0,0,0,0,0,0),0)) -> 27
... A62: ='F1 Championship'!A27 -> Sergio Perez | B62: ='F1 Championship'!C27 -> 0 | C62: =B62+IF('F1 Championship'!D27="",0,IFERROR(CHOOSE('F1 Championship'!D27,8,7,6,5,4,3,2,1,0,0,0,0,0,0,0,0,0,0,0,0),0)) -> 0 | D62: =C62+IF('F1 Championship'!E27="",0,IFERROR(CHOOSE('F1 Championship'!E27,25,18,15,12,10,8,6,4,2,1,0,0,0,0,0,0,0,0,0,0),0)) -> 0 | E62: =D62+IF('F1 Championship'!F27="",0,IFERROR(CHOOSE('F1 Championship'!F27,25,18,15,12,10,8,6,4,2,1,0,0,0,0,0,0,0,0,0,0),0)) -> 0 | F62: =E62+IF('F1 Championship'!G27="",0,IFERROR(CHOOSE('F1 Championship'!G27,25,18,15,12,10,8,6,4,2,1,0,0,0,0,0,0,0,0,0,0),0)) -> 0 | G62: =F62+IF('F1 Championship'!H27="",0,IFERROR(CHOOSE('F1 Championship'!H27,25,18,15,12,10,8,6,4,2,1,0,0,0,0,0,0,0,0,0,0),0)) -> 0 | H62: =G62+IF('F1 Championship'!I27="",0,IFERROR(CHOOSE('F1 Championship'!I27,25,18,15,12,10,8,6,4,2,1,0,0,0,0,0,0,0,0,0,0),0)) -> 0 | I62: =H62+IF('F1 Championship'!J27="",0,IFERROR(CHOOSE('F1 Championship'!J27,25,18,15,12,10,8,6,4,2,1,0,0,0,0,0,0,0,0,0,0),0)) -> 0 | J62: =I62+IF('F1 Championship'!K27="",0,IFERROR(CHOOSE('F1 Championship'!K27,25,18,15,12,10,8,6,4,2,1,0,0,0,0,0,0,0,0,0,0),0)) -> 0
...

Sheet F1 Championship
A1: 2026 FORMULA 1 DRIVERS' CHAMPIONSHIP - SCENARIO CALCULATOR
A2: Enter each driver's finishing position (1–20) in the yellow race/Sprint cells. Points, totals, rank, and gap calculate automatically. Use 0 for DNS/retirement/no points.
A4: Driver | B4: Team | C4: Starting Pts | D4: Sprint | E4: Singapore | F4: Houston | G4: Mexico | H4: Brazil | I4: Las Vegas | J4: Qatar | K4: Abu Dhabi | L4: Points | M4: Total Points | N4: Rank | O4: Point differential
A5: Kimi Antonelli | B5: Mercedes | C5: 320 | L5: =IF(E5="",0,IFERROR(CHOOSE(E5,25,18,15,12,10,8,6,4,2,1,0,0,0,0,0,0,0,0,0,0),0))+IF(F5="",0,IFERROR(CHOOSE(F5,25,18,15,12,10,8,6,4,2,1,0,0,0,0,0,0,0,0,0,0),0))+IF(G5="",0,IFERROR(CHOOSE(G5,25,18,15,12,10,8,6,4,2,1,0,0,0,0,0,0,0,0,0,0),0))+IF(H5="",0,IFERROR(CHOOSE(H5,25,18,15,12,10,8,6,4,2,1,0,0,0,0,0,0,0,0,0,0),0))+IF(I5="",0,IFERROR(CHOOSE(I5,25,18,15,12,10,8,6,4,2,1,0,0,0,0,0,0,0,0,0,0),0))+IF(J5="",0,IFERROR(CHOOSE(J5,25,18,15,12,10,8,6,4,2,1,0,0,0,0,0,0,0,0,0,0),0))+IF(K5="",0,IFERROR(CHOOSE(K5,25,18,15,12,10,8,6,4,2,1,0,0,0,0,0,0,0,0,0,0),0))+IF(D5="",0,IFERROR(CHOOSE(D5,8,7,6,5,4,3,2,1,0,0,0,0,0,0,0,0,0,0,0,0),0)) -> 0 | M5: =C5+L5 -> 320 | N5: =_xlfn.RANK.EQ(M5,$M$5:$M$27,0) -> 1 | O5: =MAX($M$5:$M$27)-M5 -> 0
A6: George Russell | B6: Mercedes | C6: 236 | L6: =IF(E6="",0,IFERROR(CHOOSE(E6,25,18,15,12,10,8,6,4,2,1,0,0,0,0,0,0,0,0,0,0),0))+IF(F6="",0,IFERROR(CHOOSE(F6,25,18,15,12,10,8,6,4,2,1,0,0,0,0,0,0,0,0,0,0),0))+IF(G6="",0,IFERROR(CHOOSE(G6,25,18,15,12,10,8,6,4,2,1,0,0,0,0,0,0,0,0,0,0),0))+IF(H6="",0,IFERROR(CHOOSE(H6,25,18,15,12,10,8,6,4,2,1,0,0,0,0,0,0,0,0,0,0),0))+IF(I6="",0,IFERROR(CHOOSE(I6,25,18,15,12,10,8,6,4,2,1,0,0,0,0,0,0,0,0,0,0),0))+IF(J6="",0,IFERROR(CHOOSE(J6,25,18,15,12,10,8,6,4,2,1,0,0,0,0,0,0,0,0,0,0),0))+IF(K6="",0,IFERROR(CHOOSE(K6,25,18,15,12,10,8,6,4,2,1,0,0,0,0,0,0,0,0,0,0),0))+IF(D6="",0,IFERROR(CHOOSE(D6,8,7,6,5,4,3,2,1,0,0,0,0,0,0,0,0,0,0,0,0),0)) -> 0 | M6: =C6+L6 -> 236 | N6: =_xlfn.RANK.EQ(M6,$M$5:$M$27,0) -> 2 | O6: =MAX($M$5:$M$27)-M6 -> 84
A7: Lewis Hamilton | B7: Ferrari | C7: 214 | L7: =IF(E7="",0,IFERROR(CHOOSE(E7,25,18,15,12,10,8,6,4,2,1,0,0,0,0,0,0,0,0,0,0),0))+IF(F7="",0,IFERROR(CHOOSE(F7,25,18,15,12,10,8,6,4,2,1,0,0,0,0,0,0,0,0,0,0),0))+IF(G7="",0,IFERROR(CHOOSE(G7,25,18,15,12,10,8,6,4,2,1,0,0,0,0,0,0,0,0,0,0),0))+IF(H7="",0,IFERROR(CHOOSE(H7,25,18,15,12,10,8,6,4,2,1,0,0,0,0,0,0,0,0,0,0),0))+IF(I7="",0,IFERROR(CHOOSE(I7,25,18,15,12,10,8,6,4,2,1,0,0,0,0,0,0,0,0,0,0),0))+IF(J7="",0,IFERROR(CHOOSE(J7,25,18,15,12,10,8,6,4,2,1,0,0,0,0,0,0,0,0,0,0),0))+IF(K7="",0,IFERROR(CHOOSE(K7,25,18,15,12,10,8,6,4,2,1,0,0,0,0,0,0,0,0,0,0),0))+IF(D7="",0,IFERROR(CHOOSE(D7,8,7,6,5,4,3,2,1,0,0,0,0,0,0,0,0,0,0,0,0),0)) -> 0 | M7: =C7+L7 -> 214 | N7: =_xlfn.RANK.EQ(M7,$M$5:$M$27,0) -> 3 | O7: =MAX($M$5:$M$27)-M7 -> 106
A8: Charles Leclerc | B8: Ferrari | C8: 191 | L8: =IF(E8="",0,IFERROR(CHOOSE(E8,25,18,15,12,10,8,6,4,2,1,0,0,0,0,0,0,0,0,0,0),0))+IF(F8="",0,IFERROR(CHOOSE(F8,25,18,15,12,10,8,6,4,2,1,0,0,0,0,0,0,0,0,0,0),0))+IF(G8="",0,IFERROR(CHOOSE(G8,25,18,15,12,10,8,6,4,2,1,0,0,0,0,0,0,0,0,0,0),0))+IF(H8="",0,IFERROR(CHOOSE(H8,25,18,15,12,10,8,6,4,2,1,0,0,0,0,0,0,0,0,0,0),0))+IF(I8="",0,IFERROR(CHOOSE(I8,25,18,15,12,10,8,6,4,2,1,0,0,0,0,0,0,0,0,0,0),0))+IF(J8="",0,IFERROR(CHOOSE(J8,25,18,15,12,10,8,6,4,2,1,0,0,0,0,0,0,0,0,0,0),0))+IF(K8="",0,IFERROR(CHOOSE(K8,25,18,15,12,10,8,6,4,2,1,0,0,0,0,0,0,0,0,0,0),0))+IF(D8="",0,IFERROR(CHOOSE(D8,8,7,6,5,4,3,2,1,0,0,0,0,0,0,0,0,0,0,0,0),0)) -> 0 | M8: =C8+L8 -> 191 | N8: =_xlfn.RANK.EQ(M8,$M$5:$M$27,0) -> 4 | O8: =MAX($M$5:$M$27)-M8 -> 129
A9: Lando Norris | B9: McLaren | C9: 188 | L9: =IF(E9="",0,IFERROR(CHOOSE(E9,25,18,15,12,10,8,6,4,2,1,0,0,0,0,0,0,0,0,0,0),0))+IF(F9="",0,IFERROR(CHOOSE(F9,25,18,15,12,10,8,6,4,2,1,0,0,0,0,0,0,0,0,0,0),0))+IF(G9="",0,IFERROR(CHOOSE(G9,25,18,15,12,10,8,6,4,2,1,0,0,0,0,0,0,0,0,0,0),0))+IF(H9="",0,IFERROR(CHOOSE(H9,25,18,15,12,10,8,6,4,2,1,0,0,0,0,0,0,0,0,0,0),0))+IF(I9="",0,IFERROR(CHOOSE(I9,25,18,15,12,10,8,6,4,2,1,0,0,0,0,0,0,0,0,0,0),0))+IF(J9="",0,IFERROR(CHOOSE(J9,25,18,15,12,10,8,6,4,2,1,0,0,0,0,0,0,0,0,0,0),0))+IF(K9="",0,IFERROR(CHOOSE(K9,25,18,15,12,10,8,6,4,2,1,0,0,0,0,0,0,0,0,0,0),0))+IF(D9="",0,IFERROR(CHOOSE(D9,8,7,6,5,4,3,2,1,0,0,0,0,0,0,0,0,0,0,0,0),0)) -> 0 | M9: =C9+L9 -> 188 | N9: =_xlfn.RANK.EQ(M9,$M$5:$M$27,0) -> 5 | O9: =MAX($M$5:$M$27)-M9 -> 132
A10: Max Verstappen | B10: Red Bull Racing | C10: 188 | L10: =IF(E10="",0,IFERROR(CHOOSE(E10,25,18,15,12,10,8,6,4,2,1,0,0,0,0,0,0,0,0,0,0),0))+IF(F10="",0,IFERROR(CHOOSE(F10,25,18,15,12,10,8,6,4,2,1,0,0,0,0,0,0,0,0,0,0),0))+IF(G10="",0,IFERROR(CHOOSE(G10,25,18,15,12,10,8,6,4,2,1,0,0,0,0,0,0,0,0,0,0),0))+IF(H10="",0,IFERROR(CHOOSE(H10,25,18,15,12,10,8,6,4,2,1,0,0,0,0,0,0,0,0,0,0),0))+IF(I10="",0,IFERROR(CHOOSE(I10,25,18,15,12,10,8,6,4,2,1,0,0,0,0,0,0,0,0,0,0),0))+IF(J10="",0,IFERROR(CHOOSE(J10,25,18,15,12,10,8,6,4,2,1,0,0,0,0,0,0,0,0,0,0),0))+IF(K10="",0,IFERROR(CHOOSE(K10,25,18,15,12,10,8,6,4,2,1,0,0,0,0,0,0,0,0,0,0),0))+IF(D10="",0,IFERROR(CHOOSE(D10,8,7,6,5,4,3,2,1,0,0,0,0,0,0,0,0,0,0,0,0),0)) -> 0 | M10: =C10+L10 -> 188 | N10: =_xlfn.RANK.EQ(M10,$M$5:$M$27,0) -> 5 | O10: =MAX($M$5:$M$27)-M10 -> 132
A11: Oscar Piastri | B11: McLaren | C11: 128 | L11: =IF(E11="",0,IFERROR(CHOOSE(E11,25,18,15,12,10,8,6,4,2,1,0,0,0,0,0,0,0,0,0,0),0))+IF(F11="",0,IFERROR(CHOOSE(F11,25,18,15,12,10,8,6,4,2,1,0,0,0,0,0,0,0,0,0,0),0))+IF(G11="",0,IFERROR(CHOOSE(G11,25,18,15,12,10,8,6,4,2,1,0,0,0,0,0,0,0,0,0,0),0))+IF(H11="",0,IFERROR(CHOOSE(H11,25,18,15,12,10,8,6,4,2,1,0,0,0,0,0,0,0,0,0,0),0))+IF(I11="",0,IFERROR(CHOOSE(I11,25,18,15,12,10,8,6,4,2,1,0,0,0,0,0,0,0,0,0,0),0))+IF(J11="",0,IFERROR(CHOOSE(J11,25,18,15,12,10,8,6,4,2,1,0,0,0,0,0,0,0,0,0,0),0))+IF(K11="",0,IFERROR(CHOOSE(K11,25,18,15,12,10,8,6,4,2,1,0,0,0,0,0,0,0,0,0,0),0))+IF(D11="",0,IFERROR(CHOOSE(D11,8,7,6,5,4,3,2,1,0,0,0,0,0,0,0,0,0,0,0,0),0)) -> 0 | M11: =C11+L11 -> 128 | N11: =_xlfn.RANK.EQ(M11,$M$5:$M$27,0) -> 7 | O11: =MAX($M$5:$M$27)-M11 -> 192
A12: Isack Hadjar | B12: Red Bull Racing | C12: 96 | L12: =IF(E12="",0,IFERROR(CHOOSE(E12,25,18,15,12,10,8,6,4,2,1,0,0,0,0,0,0,0,0,0,0),0))+IF(F12="",0,IFERROR(CHOOSE(F12,25,18,15,12,10,8,6,4,2,1,0,0,0,0,0,0,0,0,0,0),0))+IF(G12="",0,IFERROR(CHOOSE(G12,25,18,15,12,10,8,6,4,2,1,0,0,0,0,0,0,0,0,0,0),0))+IF(H12="",0,IFERROR(CHOOSE(H12,25,18,15,12,10,8,6,4,2,1,0,0,0,0,0,0,0,0,0,0),0))+IF(I12="",0,IFERROR(CHOOSE(I12,25,18,15,12,10,8,6,4,2,1,0,0,0,0,0,0,0,0,0,0),0))+IF(J12="",0,IFERROR(CHOOSE(J12,25,18,15,12,10,8,6,4,2,1,0,0,0,0,0,0,0,0,0,0),0))+IF(K12="",0,IFERROR(CHOOSE(K12,25,18,15,12,10,8,6,4,2,1,0,0,0,0,0,0,0,0,0,0),0))+IF(D12="",0,IFERROR(CHOOSE(D12,8,7,6,5,4,3,2,1,0,0,0,0,0,0,0,0,0,0,0,0),0)) -> 0 | M12: =C12+L12 -> 96 | N12: =_xlfn.RANK.EQ(M12,$M$5:$M$27,0) -> 8 | O12: =MAX($M$5:$M$27)-M12 -> 224
A13: Liam Lawson | B13: Racing Bulls | C13: 65 | L13: =IF(E13="",0,IFERROR(CHOOSE(E13,25,18,15,12,10,8,6,4,2,1,0,0,0,0,0,0,0,0,0,0),0))+IF(F13="",0,IFERROR(CHOOSE(F13,25,18,15,12,10,8,6,4,2,1,0,0,0,0,0,0,0,0,0,0),0))+IF(G13="",0,IFERROR(CHOOSE(G13,25,18,15,12,10,8,6,4,2,1,0,0,0,0,0,0,0,0,0,0),0))+IF(H13="",0,IFERROR(CHOOSE(H13,25,18,15,12,10,8,6,4,2,1,0,0,0,0,0,0,0,0,0,0),0))+IF(I13="",0,IFERROR(CHOOSE(I13,25,18,15,12,10,8,6,4,2,1,0,0,0,0,0,0,0,0,0,0),0))+IF(J13="",0,IFERROR(CHOOSE(J13,25,18,15,12,10,8,6,4,2,1,0,0,0,0,0,0,0,0,0,0),0))+IF(K13="",0,IFERROR(CHOOSE(K13,25,18,15,12,10,8,6,4,2,1,0,0,0,0,0,0,0,0,0,0),0))+IF(D13="",0,IFERROR(CHOOSE(D13,8,7,6,5,4,3,2,1,0,0,0,0,0,0,0,0,0,0,0,0),0)) -> 0 | M13: =C13+L13 -> 65 | N13: =_xlfn.RANK.EQ(M13,$M$5:$M$27,0) -> 9 | O13: =MAX($M$5:$M$27)-M13 -> 255
A14: Pierre Gasly | B14: Alpine | C14: 41 | L14: =IF(E14="",0,IFERROR(CHOOSE(E14,25,18,15,12,10,8,6,4,2,1,0,0,0,0,0,0,0,0,0,0),0))+IF(F14="",0,IFERROR(CHOOSE(F14,25,18,15,12,10,8,6,4,2,1,0,0,0,0,0,0,0,0,0,0),0))+IF(G14="",0,IFERROR(CHOOSE(G14,25,18,15,12,10,8,6,4,2,1,0,0,0,0,0,0,0,0,0,0),0))+IF(H14="",0,IFERROR(CHOOSE(H14,25,18,15,12,10,8,6,4,2,1,0,0,0,0,0,0,0,0,0,0),0))+IF(I14="",0,IFERROR(CHOOSE(I14,25,18,15,12,10,8,6,4,2,1,0,0,0,0,0,0,0,0,0,0),0))+IF(J14="",0,IFERROR(CHOOSE(J14,25,18,15,12,10,8,6,4,2,1,0,0,0,0,0,0,0,0,0,0),0))+IF(K14="",0,IFERROR(CHOOSE(K14,25,18,15,12,10,8,6,4,2,1,0,0,0,0,0,0,0,0,0,0),0))+IF(D14="",0,IFERROR(CHOOSE(D14,8,7,6,5,4,3,2,1,0,0,0,0,0,0,0,0,0,0,0,0),0)) -> 0 | M14: =C14+L14 -> 41 | N14: =_xlfn.RANK.EQ(M14,$M$5:$M$27,0) -> 10 | O14: =MAX($M$5:$M$27)-M14 -> 279
A15: Arvid Lindblad | B15: Racing Bulls | C15: 38 | L15: =IF(E15="",0,IFERROR(CHOOSE(E15,25,18,15,12,10,8,6,4,2,1,0,0,0,0,0,0,0,0,0,0),0))+IF(F15="",0,IFERROR(CHOOSE(F15,25,18,15,12,10,8,6,4,2,1,0,0,0,0,0,0,0,0,0,0),0))+IF(G15="",0,IFERROR(CHOOSE(G15,25,18,15,12,10,8,6,4,2,1,0,0,0,0,0,0,0,0,0,0),0))+IF(H15="",0,IFERROR(CHOOSE(H15,25,18,15,12,10,8,6,4,2,1,0,0,0,0,0,0,0,0,0,0),0))+IF(I15="",0,IFERROR(CHOOSE(I15,25,18,15,12,10,8,6,4,2,1,0,0,0,0,0,0,0,0,0,0),0))+IF(J15="",0,IFERROR(CHOOSE(J15,25,18,15,12,10,8,6,4,2,1,0,0,0,0,0,0,0,0,0,0),0))+IF(K15="",0,IFERROR(CHOOSE(K15,25,18,15,12,10,8,6,4,2,1,0,0,0,0,0,0,0,0,0,0),0))+IF(D15="",0,IFERROR(CHOOSE(D15,8,7,6,5,4,3,2,1,0,0,0,0,0,0,0,0,0,0,0,0),0)) -> 0 | M15: =C15+L15 -> 38 | N15: =_xlfn.RANK.EQ(M15,$M$5:$M$27,0) -> 11 | O15: =MAX($M$5:$M$27)-M15 -> 282
A16: Franco Colapinto | B16: Alpine | C16: 27 | L16: =IF(E16="",0,IFERROR(CHOOSE(E16,25,18,15,12,10,8,6,4,2,1,0,0,0,0,0,0,0,0,0,0),0))+IF(F16="",0,IFERROR(CHOOSE(F16,25,18,15,12,10,8,6,4,2,1,0,0,0,0,0,0,0,0,0,0),0))+IF(G16="",0,IFERROR(CHOOSE(G16,25,18,15,12,10,8,6,4,2,1,0,0,0,0,0,0,0,0,0,0),0))+IF(H16="",0,IFERROR(CHOOSE(H16,25,18,15,12,10,8,6,4,2,1,0,0,0,0,0,0,0,0,0,0),0))+IF(I16="",0,IFERROR(CHOOSE(I16,25,18,15,12,10,8,6,4,2,1,0,0,0,0,0,0,0,0,0,0),0))+IF(J16="",0,IFERROR(CHOOSE(J16,25,18,15,12,10,8,6,4,2,1,0,0,0,0,0,0,0,0,0,0),0))+IF(K16="",0,IFERROR(CHOOSE(K16,25,18,15,12,10,8,6,4,2,1,0,0,0,0,0,0,0,0,0,0),0))+IF(D16="",0,IFERROR(CHOOSE(D16,8,7,6,5,4,3,2,1,0,0,0,0,0,0,0,0,0,0,0,0),0)) -> 0 | M16: =C16+L16 -> 27 | N16: =_xlfn.RANK.EQ(M16,$M$5:$M$27,0) -> 12 | O16: =MAX($M$5:$M$27)-M16 -> 293
... A27: Sergio Perez | B27: Cadillac | C27: 0 | L27: =IF(E27="",0,IFERROR(CHOOSE(E27,25,18,15,12,10,8,6,4,2,1,0,0,0,0,0,0,0,0,0,0),0))+IF(F27="",0,IFERROR(CHOOSE(F27,25,18,15,12,10,8,6,4,2,1,0,0,0,0,0,0,0,0,0,0),0))+IF(G27="",0,IFERROR(CHOOSE(G27,25,18,15,12,10,8,6,4,2,1,0,0,0,0,0,0,0,0,0,0),0))+IF(H27="",0,IFERROR(CHOOSE(H27,25,18,15,12,10,8,6,4,2,1,0,0,0,0,0,0,0,0,0,0),0))+IF(I27="",0,IFERROR(CHOOSE(I27,25,18,15,12,10,8,6,4,2,1,0,0,0,0,0,0,0,0,0,0),0))+IF(J27="",0,IFERROR(CHOOSE(J27,25,18,15,12,10,8,6,4,2,1,0,0,0,0,0,0,0,0,0,0),0))+IF(K27="",0,IFERROR(CHOOSE(K27,25,18,15,12,10,8,6,4,2,1,0,0,0,0,0,0,0,0,0,0),0))+IF(D27="",0,IFERROR(CHOOSE(D27,8,7,6,5,4,3,2,1,0,0,0,0,0,0,0,0,0,0,0,0),0)) -> 0 | M27: =C27+L27 -> 0 | N27: =_xlfn.RANK.EQ(M27,$M$5:$M$27,0) -> 21 | O27: =MAX($M$5:$M$27)-M27 -> 320

Sheet Points Reference
A1: Grand Prix Points | D1: Sprint Points
A2: Finishing position | B2: Points | D2: Finishing position | E2: Points
A3: 1 | B3: 25 | D3: 1 | E3: 8
A4: 2 | B4: 18 | D4: 2 | E4: 7
A5: 3 | B5: 15 | D5: 3 | E5: 6
A6: 4 | B6: 12 | D6: 4 | E6: 5
A7: 5 | B7: 10 | D7: 5 | E7: 4
A8: 6 | B8: 8 | D8: 6 | E8: 3
A9: 7 | B9: 6 | D9: 7 | E9: 2
A10: 8 | B10: 4 | D10: 8 | E10: 1
A11: 9 | B11: 2 | D11: 9 | E11: 0
A12: 10 | B12: 1 | D12: 10 | E12: 0
A13: 11 | B13: 0 | D13: 11 | E13: 0
A14: 12 | B14: 0 | D14: 12 | E14: 0
... A22: 20 | B22: 0 | D22: 20 | E22: 0
